2024-10-14 21:16:57,351 [DEBUG    ][application] [s2s-app.py][main] main関数の処理: start
2024-10-14 21:16:57,355 [DEBUG    ][application] [s2s-app.py][main] main関数の処理: end
2024-10-14 21:16:57,356 [DEBUG    ][application] [s2s-app.py][main] 処理時間: 0.004 s
2024-10-14 21:16:59,324 [DEBUG    ][application] [s2s-app.py][main] main関数の処理: start
2024-10-14 21:16:59,329 [DEBUG    ][application] [record_audio.py][record_audio] 録音データの取得: start
2024-10-14 21:17:12,384 [DEBUG    ][application] [record_audio.py][record_audio] 録音データの取得: end
2024-10-14 21:17:12,384 [DEBUG    ][application] [record_audio.py][record_audio] 処理時間: 13.055 s
2024-10-14 21:17:12,385 [DEBUG    ][application] [transcribe.py][transcribe] 音声からテキストに変換（トランスクリプション）: start
2024-10-14 21:17:14,139 [DEBUG    ][application] [transcribe.py][transcribe] 音声からテキストに変換（トランスクリプション）: end
2024-10-14 21:17:14,140 [DEBUG    ][application] [transcribe.py][transcribe] 処理時間: 1.754 s
2024-10-14 21:17:14,142 [DEBUG    ][application] [chat_llm.py][chat_llm] テキストを使用して生成AIに質問: start
2024-10-14 21:17:15,635 [DEBUG    ][application] [chat_llm.py][chat_llm] テキストを使用して生成AIに質問: end
2024-10-14 21:17:15,636 [DEBUG    ][application] [chat_llm.py][chat_llm] 処理時間: 1.493 s
2024-10-14 21:17:15,639 [DEBUG    ][application] [text_to_speech.py][text_to_speech] 音声からテキストに変換: start
2024-10-14 21:17:19,720 [ERROR    ][application] [text_to_speech.py][text_to_speech] Exception occered in 'text_to_speech': HTTPConnectionPool(host='localhost', port=50021): Max retries exceeded with url: /audio_query?text=%E3%81%94%E3%81%A1%E3%81%9D%E3%81%86%E3%81%95%E3%81%BE%E3%81%A7%E3%81%97%E3%81%9F%EF%BC%81%E3%81%8A%E9%A3%9F%E4%BA%8B%E3%81%AF%E3%81%84%E3%81%8B%E3%81%8C%E3%81%A7%E3%81%97%E3%81%9F%E3%81%8B%EF%BC%9F%E4%BD%95%E3%81%8B%E7%89%B9%E5%88%A5%E3%81%AA%E6%96%99%E7%90%86%E3%82%92%E6%A5%BD%E3%81%97%E3%81%BF%E3%81%BE%E3%81%97%E3%81%9F%E3%81%8B%EF%BC%9F&speaker=3 (Caused by NewConnectionError('<urllib3.connection.HTTPConnection object at 0x000001A4F5BC0980>: Failed to establish a new connection: [WinError 10061] 対象のコンピューターによって拒否されたため、接続できませんでした。'))
2024-10-14 21:17:19,729 [ERROR    ][application] Traceback (most recent call last):
  File "C:\Users\funky\AppData\Local\Programs\Python\Python312\Lib\site-packages\urllib3\connection.py", line 199, in _new_conn
    sock = connection.create_connection(
           ^^^^^^^^^^^^^^^^^^^^^^^^^^^^^
  File "C:\Users\funky\AppData\Local\Programs\Python\Python312\Lib\site-packages\urllib3\util\connection.py", line 85, in create_connection
    raise err
  File "C:\Users\funky\AppData\Local\Programs\Python\Python312\Lib\site-packages\urllib3\util\connection.py", line 73, in create_connection
    sock.connect(sa)
ConnectionRefusedError: [WinError 10061] 対象のコンピューターによって拒否されたため、接続できませんでした。

The above exception was the direct cause of the following exception:

Traceback (most recent call last):
  File "C:\Users\funky\AppData\Local\Programs\Python\Python312\Lib\site-packages\urllib3\connectionpool.py", line 789, in urlopen
    response = self._make_request(
               ^^^^^^^^^^^^^^^^^^^
  File "C:\Users\funky\AppData\Local\Programs\Python\Python312\Lib\site-packages\urllib3\connectionpool.py", line 495, in _make_request
    conn.request(
  File "C:\Users\funky\AppData\Local\Programs\Python\Python312\Lib\site-packages\urllib3\connection.py", line 441, in request
    self.endheaders()
  File "C:\Users\funky\AppData\Local\Programs\Python\Python312\Lib\http\client.py", line 1331, in endheaders
    self._send_output(message_body, encode_chunked=encode_chunked)
  File "C:\Users\funky\AppData\Local\Programs\Python\Python312\Lib\http\client.py", line 1091, in _send_output
    self.send(msg)
  File "C:\Users\funky\AppData\Local\Programs\Python\Python312\Lib\http\client.py", line 1035, in send
    self.connect()
  File "C:\Users\funky\AppData\Local\Programs\Python\Python312\Lib\site-packages\urllib3\connection.py", line 279, in connect
    self.sock = self._new_conn()
                ^^^^^^^^^^^^^^^^
  File "C:\Users\funky\AppData\Local\Programs\Python\Python312\Lib\site-packages\urllib3\connection.py", line 214, in _new_conn
    raise NewConnectionError(
urllib3.exceptions.NewConnectionError: <urllib3.connection.HTTPConnection object at 0x000001A4F5BC0980>: Failed to establish a new connection: [WinError 10061] 対象のコンピューターによって拒否されたため、接続できませんでした。

The above exception was the direct cause of the following exception:

Traceback (most recent call last):
  File "C:\Users\funky\AppData\Local\Programs\Python\Python312\Lib\site-packages\requests\adapters.py", line 667, in send
    resp = conn.urlopen(
           ^^^^^^^^^^^^^
  File "C:\Users\funky\AppData\Local\Programs\Python\Python312\Lib\site-packages\urllib3\connectionpool.py", line 843, in urlopen
    retries = retries.increment(
              ^^^^^^^^^^^^^^^^^^
  File "C:\Users\funky\AppData\Local\Programs\Python\Python312\Lib\site-packages\urllib3\util\retry.py", line 519, in increment
    raise MaxRetryError(_pool, url, reason) from reason  # type: ignore[arg-type]
    ^^^^^^^^^^^^^^^^^^^^^^^^^^^^^^^^^^^^^^^^^^^^^^^^^^^
urllib3.exceptions.MaxRetryError: HTTPConnectionPool(host='localhost', port=50021): Max retries exceeded with url: /audio_query?text=%E3%81%94%E3%81%A1%E3%81%9D%E3%81%86%E3%81%95%E3%81%BE%E3%81%A7%E3%81%97%E3%81%9F%EF%BC%81%E3%81%8A%E9%A3%9F%E4%BA%8B%E3%81%AF%E3%81%84%E3%81%8B%E3%81%8C%E3%81%A7%E3%81%97%E3%81%9F%E3%81%8B%EF%BC%9F%E4%BD%95%E3%81%8B%E7%89%B9%E5%88%A5%E3%81%AA%E6%96%99%E7%90%86%E3%82%92%E6%A5%BD%E3%81%97%E3%81%BF%E3%81%BE%E3%81%97%E3%81%9F%E3%81%8B%EF%BC%9F&speaker=3 (Caused by NewConnectionError('<urllib3.connection.HTTPConnection object at 0x000001A4F5BC0980>: Failed to establish a new connection: [WinError 10061] 対象のコンピューターによって拒否されたため、接続できませんでした。'))

During handling of the above exception, another exception occurred:

Traceback (most recent call last):
  File "C:\Users\funky\Documents\_work\M5Stack\202410_STT-GPT-TTSアプリ\src\speach-to-voicevox-speach-sample\app\util\logger\loggingUtil.py", line 51, in wrapper
    result = func(*args, **kwargs)
             ^^^^^^^^^^^^^^^^^^^^^
  File "C:\Users\funky\Documents\_work\M5Stack\202410_STT-GPT-TTSアプリ\src\speach-to-voicevox-speach-sample\app\core\text_to_speech.py", line 12, in text_to_speech
    response_audio = requests.post(f"http://localhost:50021/audio_query?text={text}&speaker={speaker_id}")
                     ^^^^^^^^^^^^^^^^^^^^^^^^^^^^^^^^^^^^^^^^^^^^^^^^^^^^^^^^^^^^^^^^^^^^^^^^^^^^^^^^^^^^^
  File "C:\Users\funky\AppData\Local\Programs\Python\Python312\Lib\site-packages\requests\api.py", line 115, in post
    return request("post", url, data=data, json=json, **kwargs)
           ^^^^^^^^^^^^^^^^^^^^^^^^^^^^^^^^^^^^^^^^^^^^^^^^^^^^
  File "C:\Users\funky\AppData\Local\Programs\Python\Python312\Lib\site-packages\requests\api.py", line 59, in request
    return session.request(method=method, url=url, **kwargs)
           ^^^^^^^^^^^^^^^^^^^^^^^^^^^^^^^^^^^^^^^^^^^^^^^^^
  File "C:\Users\funky\AppData\Local\Programs\Python\Python312\Lib\site-packages\requests\sessions.py", line 589, in request
    resp = self.send(prep, **send_kwargs)
           ^^^^^^^^^^^^^^^^^^^^^^^^^^^^^^
  File "C:\Users\funky\AppData\Local\Programs\Python\Python312\Lib\site-packages\requests\sessions.py", line 703, in send
    r = adapter.send(request, **kwargs)
        ^^^^^^^^^^^^^^^^^^^^^^^^^^^^^^^
  File "C:\Users\funky\AppData\Local\Programs\Python\Python312\Lib\site-packages\requests\adapters.py", line 700, in send
    raise ConnectionError(e, request=request)
requests.exceptions.ConnectionError: HTTPConnectionPool(host='localhost', port=50021): Max retries exceeded with url: /audio_query?text=%E3%81%94%E3%81%A1%E3%81%9D%E3%81%86%E3%81%95%E3%81%BE%E3%81%A7%E3%81%97%E3%81%9F%EF%BC%81%E3%81%8A%E9%A3%9F%E4%BA%8B%E3%81%AF%E3%81%84%E3%81%8B%E3%81%8C%E3%81%A7%E3%81%97%E3%81%9F%E3%81%8B%EF%BC%9F%E4%BD%95%E3%81%8B%E7%89%B9%E5%88%A5%E3%81%AA%E6%96%99%E7%90%86%E3%82%92%E6%A5%BD%E3%81%97%E3%81%BF%E3%81%BE%E3%81%97%E3%81%9F%E3%81%8B%EF%BC%9F&speaker=3 (Caused by NewConnectionError('<urllib3.connection.HTTPConnection object at 0x000001A4F5BC0980>: Failed to establish a new connection: [WinError 10061] 対象のコンピューターによって拒否されたため、接続できませんでした。'))

2024-10-14 21:17:19,743 [DEBUG    ][application] [text_to_speech.py][text_to_speech] 音声からテキストに変換: end
2024-10-14 21:17:19,743 [DEBUG    ][application] [text_to_speech.py][text_to_speech] 処理時間: 4.103 s
2024-10-14 21:17:19,744 [ERROR    ][application] [s2s-app.py][main] Caught Error Message : HTTPConnectionPool(host='localhost', port=50021): Max retries exceeded with url: /audio_query?text=%E3%81%94%E3%81%A1%E3%81%9D%E3%81%86%E3%81%95%E3%81%BE%E3%81%A7%E3%81%97%E3%81%9F%EF%BC%81%E3%81%8A%E9%A3%9F%E4%BA%8B%E3%81%AF%E3%81%84%E3%81%8B%E3%81%8C%E3%81%A7%E3%81%97%E3%81%9F%E3%81%8B%EF%BC%9F%E4%BD%95%E3%81%8B%E7%89%B9%E5%88%A5%E3%81%AA%E6%96%99%E7%90%86%E3%82%92%E6%A5%BD%E3%81%97%E3%81%BF%E3%81%BE%E3%81%97%E3%81%9F%E3%81%8B%EF%BC%9F&speaker=3 (Caused by NewConnectionError('<urllib3.connection.HTTPConnection object at 0x000001A4F5BC0980>: Failed to establish a new connection: [WinError 10061] 対象のコンピューターによって拒否されたため、接続できませんでした。'))
2024-10-14 21:17:19,744 [DEBUG    ][application] [s2s-app.py][main] main関数の処理: end
2024-10-14 21:17:19,745 [DEBUG    ][application] [s2s-app.py][main] 処理時間: 20.420 s
